Workbook

Sheet Solucao
A3: 1 - A Empresa Analisada Gerou Lucro ou Prejuízo no Período?
B5: Tabela 1 - Análise de geração de Lucro por País e por Período
B6: Países | C6: 43344 | D6: 43374 | E6: 43405 | F6: 43435 | G6: 43466 | H6: 43497 | I6: 43525 | J6: 43556 | K6: 43586 | L6: 43617 | M6: 43647 | N6: 43678 | O6: 43709 | P6: 43739 | Q6: 43770 | R6: 43800 | S6: Total
B7: Canadá | C7: =SUMIFS(BD!$H:$H,BD!$B:$B,Solucao!$B7,BD!$I:$I,Solucao!C$6) -> 66365.21 | D7: =SUMIFS(BD!$H:$H,BD!$B:$B,Solucao!$B7,BD!$I:$I,Solucao!D$6) -> 266689.08 | E7: =SUMIFS(BD!$H:$H,BD!$B:$B,Solucao!$B7,BD!$I:$I,Solucao!E$6) -> 202210.1 | F7: =SUMIFS(BD!$H:$H,BD!$B:$B,Solucao!$B7,BD!$I:$I,Solucao!F$6) -> 235467.79 | G7: =SUMIFS(BD!$H:$H,BD!$B:$B,Solucao!$B7,BD!$I:$I,Solucao!G$6) -> 137144.49 | H7: =SUMIFS(BD!$H:$H,BD!$B:$B,Solucao!$B7,BD!$I:$I,Solucao!H$6) -> 249893.88 | I7: =SUMIFS(BD!$H:$H,BD!$B:$B,Solucao!$B7,BD!$I:$I,Solucao!I$6) -> 59900.5 | J7: =SUMIFS(BD!$H:$H,BD!$B:$B,Solucao!$B7,BD!$I:$I,Solucao!J$6) -> 230796.45 | ... R7: =SUMIFS(BD!$H:$H,BD!$B:$B,Solucao!$B7,BD!$I:$I,Solucao!R$6) -> 674531.44 | S7: =SUM(C7:R7) -> 3311819
B8: Alemanha | C8: =SUMIFS(BD!$H:$H,BD!$B:$B,Solucao!$B8,BD!$I:$I,Solucao!C$6) -> 198086.16 | D8: =SUMIFS(BD!$H:$H,BD!$B:$B,Solucao!$B8,BD!$I:$I,Solucao!D$6) -> 591456.76 | E8: =SUMIFS(BD!$H:$H,BD!$B:$B,Solucao!$B8,BD!$I:$I,Solucao!E$6) -> 183404.9 | F8: =SUMIFS(BD!$H:$H,BD!$B:$B,Solucao!$B8,BD!$I:$I,Solucao!F$6) -> 128097.85 | G8: =SUMIFS(BD!$H:$H,BD!$B:$B,Solucao!$B8,BD!$I:$I,Solucao!G$6) -> 58587.11 | H8: =SUMIFS(BD!$H:$H,BD!$B:$B,Solucao!$B8,BD!$I:$I,Solucao!H$6) -> 191413.07 | I8: =SUMIFS(BD!$H:$H,BD!$B:$B,Solucao!$B8,BD!$I:$I,Solucao!I$6) -> 64259.59 | J8: =SUMIFS(BD!$H:$H,BD!$B:$B,Solucao!$B8,BD!$I:$I,Solucao!J$6) -> 174819.46 | ... R8: =SUMIFS(BD!$H:$H,BD!$B:$B,Solucao!$B8,BD!$I:$I,Solucao!R$6) -> 368946.44 | S8: =SUM(C8:R8) -> 3411122.2
B9: França | C9: =SUMIFS(BD!$H:$H,BD!$B:$B,Solucao!$B9,BD!$I:$I,Solucao!C$6) -> 163646.59 | D9: =SUMIFS(BD!$H:$H,BD!$B:$B,Solucao!$B9,BD!$I:$I,Solucao!D$6) -> 431439.56 | E9: =SUMIFS(BD!$H:$H,BD!$B:$B,Solucao!$B9,BD!$I:$I,Solucao!E$6) -> 119334.8 | F9: =SUMIFS(BD!$H:$H,BD!$B:$B,Solucao!$B9,BD!$I:$I,Solucao!F$6) -> 65419.32 | G9: =SUMIFS(BD!$H:$H,BD!$B:$B,Solucao!$B9,BD!$I:$I,Solucao!G$6) -> 244987.24 | H9: =SUMIFS(BD!$H:$H,BD!$B:$B,Solucao!$B9,BD!$I:$I,Solucao!H$6) -> 322598.96 | I9: =SUMIFS(BD!$H:$H,BD!$B:$B,Solucao!$B9,BD!$I:$I,Solucao!I$6) -> 84952.75 | J9: =SUMIFS(BD!$H:$H,BD!$B:$B,Solucao!$B9,BD!$I:$I,Solucao!J$6) -> 85575.195 | ... R9: =SUMIFS(BD!$H:$H,BD!$B:$B,Solucao!$B9,BD!$I:$I,Solucao!R$6) -> 398175.7 | S9: =SUM(C9:R9) -> 3477575.1
B10: Chile | C10: =SUMIFS(BD!$H:$H,BD!$B:$B,Solucao!$B10,BD!$I:$I,Solucao!C$6) -> 110315.2 | D10: =SUMIFS(BD!$H:$H,BD!$B:$B,Solucao!$B10,BD!$I:$I,Solucao!D$6) -> 128860.46 | E10: =SUMIFS(BD!$H:$H,BD!$B:$B,Solucao!$B10,BD!$I:$I,Solucao!E$6) -> 153294.36 | F10: =SUMIFS(BD!$H:$H,BD!$B:$B,Solucao!$B10,BD!$I:$I,Solucao!F$6) -> 150701.14 | G10: =SUMIFS(BD!$H:$H,BD!$B:$B,Solucao!$B10,BD!$I:$I,Solucao!G$6) -> 250287.85 | H10: =SUMIFS(BD!$H:$H,BD!$B:$B,Solucao!$B10,BD!$I:$I,Solucao!H$6) -> 215471.32 | I10: =SUMIFS(BD!$H:$H,BD!$B:$B,Solucao!$B10,BD!$I:$I,Solucao!I$6) -> 142129.56 | J10: =SUMIFS(BD!$H:$H,BD!$B:$B,Solucao!$B10,BD!$I:$I,Solucao!J$6) -> 168409.49 | ... R10: =SUMIFS(BD!$H:$H,BD!$B:$B,Solucao!$B10,BD!$I:$I,Solucao!R$6) -> 219848.22 | S10: =SUM(C10:R10) -> 2658929.8
B11: EUA | C11: =SUMIFS(BD!$H:$H,BD!$B:$B,Solucao!$B11,BD!$I:$I,Solucao!C$6) -> 177685.87 | D11: =SUMIFS(BD!$H:$H,BD!$B:$B,Solucao!$B11,BD!$I:$I,Solucao!D$6) -> 217220.94 | E11: =SUMIFS(BD!$H:$H,BD!$B:$B,Solucao!$B11,BD!$I:$I,Solucao!E$6) -> 102633.14 | F11: =SUMIFS(BD!$H:$H,BD!$B:$B,Solucao!$B11,BD!$I:$I,Solucao!F$6) -> 49325.58 | G11: =SUMIFS(BD!$H:$H,BD!$B:$B,Solucao!$B11,BD!$I:$I,Solucao!G$6) -> 116443.48 | H11: =SUMIFS(BD!$H:$H,BD!$B:$B,Solucao!$B11,BD!$I:$I,Solucao!H$6) -> 166919.26 | I11: =SUMIFS(BD!$H:$H,BD!$B:$B,Solucao!$B11,BD!$I:$I,Solucao!I$6) -> 150248.47 | J11: =SUMIFS(BD!$H:$H,BD!$B:$B,Solucao!$B11,BD!$I:$I,Solucao!J$6) -> 164046.97 | ... R11: =SUMIFS(BD!$H:$H,BD!$B:$B,Solucao!$B11,BD!$I:$I,Solucao!R$6) -> 147979.1 | S11: =SUM(C11:R11) -> 2835405.9
B12: Total | C12: =SUM(C7:C11) -> 716099.03 | D12: =SUM(D7:D11) -> 1635666.8 | E12: =SUM(E7:E11) -> 760877.3 | F12: =SUM(F7:F11) -> 629011.68 | G12: =SUM(G7:G11) -> 807450.18 | H12: =SUM(H7:H11) -> 1146296.5 | I12: =SUM(I7:I11) -> 501490.87 | J12: =SUM(J7:J11) -> 823647.57 | ... S12: =SUM(S7:S11) -> 15694852
B14: Resposta: A empresa gerou Lucro e o valor total aproximado foi de USD 15,7 MM
A17: 2 - Qual Faturamento Médio Mensal desta Empresa? / 3 - Qual mês foi registrado o período de maior faturamento da empresa?
B19: Tabela 2 - Análise do Faturamento por País e por Período
B20: Países | C20: 43344 | D20: 43374 | E20: 43405 | F20: 43435 | G20: 43466 | H20: 43497 | I20: 43525 | J20: 43556 | K20: 43586 | L20: 43617 | M20: 43647 | N20: 43678 | O20: 43709 | P20: 43739 | Q20: 43770 | R20: 43800 | S20: Faturamento Médio
B21: Canadá | C21: =SUMIFS(BD!$F:$F,BD!$B:$B,Solucao!$B21,BD!$I:$I,Solucao!C$20) -> 939195.21 | D21: =SUMIFS(BD!$F:$F,BD!$B:$B,Solucao!$B21,BD!$I:$I,Solucao!D$20) -> 1229608.3 | E21: =SUMIFS(BD!$F:$F,BD!$B:$B,Solucao!$B21,BD!$I:$I,Solucao!E$20) -> 1419826.1 | F21: =SUMIFS(BD!$F:$F,BD!$B:$B,Solucao!$B21,BD!$I:$I,Solucao!F$20) -> 1587259.2 | G21: =SUMIFS(BD!$F:$F,BD!$B:$B,Solucao!$B21,BD!$I:$I,Solucao!G$20) -> 1186256.5 | H21: =SUMIFS(BD!$F:$F,BD!$B:$B,Solucao!$B21,BD!$I:$I,Solucao!H$20) -> 1482166 | I21: =SUMIFS(BD!$F:$F,BD!$B:$B,Solucao!$B21,BD!$I:$I,Solucao!I$20) -> 811132.5 | J21: =SUMIFS(BD!$F:$F,BD!$B:$B,Solucao!$B21,BD!$I:$I,Solucao!J$20) -> 1593562.9 | ... R21: =SUMIFS(BD!$F:$F,BD!$B:$B,Solucao!$B21,BD!$I:$I,Solucao!R$20) -> 3959729.4 | S21: =AVERAGE(C21:R21) -> 1555478.4
B22: Alemanha | C22: =SUMIFS(BD!$F:$F,BD!$B:$B,Solucao!$B22,BD!$I:$I,Solucao!C$20) -> 1095488.2 | D22: =SUMIFS(BD!$F:$F,BD!$B:$B,Solucao!$B22,BD!$I:$I,Solucao!D$20) -> 2555442.6 | E22: =SUMIFS(BD!$F:$F,BD!$B:$B,Solucao!$B22,BD!$I:$I,Solucao!E$20) -> 1718947.9 | F22: =SUMIFS(BD!$F:$F,BD!$B:$B,Solucao!$B22,BD!$I:$I,Solucao!F$20) -> 857856.85 | G22: =SUMIFS(BD!$F:$F,BD!$B:$B,Solucao!$B22,BD!$I:$I,Solucao!G$20) -> 874935.11 | H22: =SUMIFS(BD!$F:$F,BD!$B:$B,Solucao!$B22,BD!$I:$I,Solucao!H$20) -> 1347335.9 | I22: =SUMIFS(BD!$F:$F,BD!$B:$B,Solucao!$B22,BD!$I:$I,Solucao!I$20) -> 479509.59 | J22: =SUMIFS(BD!$F:$F,BD!$B:$B,Solucao!$B22,BD!$I:$I,Solucao!J$20) -> 1394813.5 | ... R22: =SUMIFS(BD!$F:$F,BD!$B:$B,Solucao!$B22,BD!$I:$I,Solucao!R$20) -> 2283342.4 | S22: =AVERAGE(C22:R22) -> 1469083.8
B23: França | C23: =SUMIFS(BD!$F:$F,BD!$B:$B,Solucao!$B23,BD!$I:$I,Solucao!C$20) -> 821599.59 | D23: =SUMIFS(BD!$F:$F,BD!$B:$B,Solucao!$B23,BD!$I:$I,Solucao!D$20) -> 2390477 | E23: =SUMIFS(BD!$F:$F,BD!$B:$B,Solucao!$B23,BD!$I:$I,Solucao!E$20) -> 985577.3 | F23: =SUMIFS(BD!$F:$F,BD!$B:$B,Solucao!$B23,BD!$I:$I,Solucao!F$20) -> 935141.32 | G23: =SUMIFS(BD!$F:$F,BD!$B:$B,Solucao!$B23,BD!$I:$I,Solucao!G$20) -> 1544720.7 | H23: =SUMIFS(BD!$F:$F,BD!$B:$B,Solucao!$B23,BD!$I:$I,Solucao!H$20) -> 1537438.5 | I23: =SUMIFS(BD!$F:$F,BD!$B:$B,Solucao!$B23,BD!$I:$I,Solucao!I$20) -> 1559748.8 | J23: =SUMIFS(BD!$F:$F,BD!$B:$B,Solucao!$B23,BD!$I:$I,Solucao!J$20) -> 1332862.7 | ... R23: =SUMIFS(BD!$F:$F,BD!$B:$B,Solucao!$B23,BD!$I:$I,Solucao!R$20) -> 2389929.2 | S23: =AVERAGE(C23:R23) -> 1522135.8
B24: Chile | C24: =SUMIFS(BD!$F:$F,BD!$B:$B,Solucao!$B24,BD!$I:$I,Solucao!C$20) -> 646694.2 | D24: =SUMIFS(BD!$F:$F,BD!$B:$B,Solucao!$B24,BD!$I:$I,Solucao!D$20) -> 1166052.6 | E24: =SUMIFS(BD!$F:$F,BD!$B:$B,Solucao!$B24,BD!$I:$I,Solucao!E$20) -> 1616106.4 | F24: =SUMIFS(BD!$F:$F,BD!$B:$B,Solucao!$B24,BD!$I:$I,Solucao!F$20) -> 1325568.1 | G24: =SUMIFS(BD!$F:$F,BD!$B:$B,Solucao!$B24,BD!$I:$I,Solucao!G$20) -> 1655822.8 | H24: =SUMIFS(BD!$F:$F,BD!$B:$B,Solucao!$B24,BD!$I:$I,Solucao!H$20) -> 1597700.4 | I24: =SUMIFS(BD!$F:$F,BD!$B:$B,Solucao!$B24,BD!$I:$I,Solucao!I$20) -> 946494.56 | J24: =SUMIFS(BD!$F:$F,BD!$B:$B,Solucao!$B24,BD!$I:$I,Solucao!J$20) -> 1026911.5 | ... R24: =SUMIFS(BD!$F:$F,BD!$B:$B,Solucao!$B24,BD!$I:$I,Solucao!R$20) -> 1633894.7 | S24: =AVERAGE(C24:R24) -> 1309334.5
B25: EUA | C25: =SUMIFS(BD!$F:$F,BD!$B:$B,Solucao!$B25,BD!$I:$I,Solucao!C$20) -> 981022.87 | D25: =SUMIFS(BD!$F:$F,BD!$B:$B,Solucao!$B25,BD!$I:$I,Solucao!D$20) -> 1954030.7 | E25: =SUMIFS(BD!$F:$F,BD!$B:$B,Solucao!$B25,BD!$I:$I,Solucao!E$20) -> 1526745.6 | F25: =SUMIFS(BD!$F:$F,BD!$B:$B,Solucao!$B25,BD!$I:$I,Solucao!F$20) -> 662615.58 | G25: =SUMIFS(BD!$F:$F,BD!$B:$B,Solucao!$B25,BD!$I:$I,Solucao!G$20) -> 1346026.5 | H25: =SUMIFS(BD!$F:$F,BD!$B:$B,Solucao!$B25,BD!$I:$I,Solucao!H$20) -> 1332890.7 | I25: =SUMIFS(BD!$F:$F,BD!$B:$B,Solucao!$B25,BD!$I:$I,Solucao!I$20) -> 1789974.5 | J25: =SUMIFS(BD!$F:$F,BD!$B:$B,Solucao!$B25,BD!$I:$I,Solucao!J$20) -> 1616624.5 | ... R25: =SUMIFS(BD!$F:$F,BD!$B:$B,Solucao!$B25,BD!$I:$I,Solucao!R$20) -> 1731892.1 | S25: =AVERAGE(C25:R25) -> 1564364.4
B26: Total | C26: =SUM(C21:C25) -> 4484000 | D26: =SUM(D21:D25) -> 9295611.1 | E26: =SUM(E21:E25) -> 7267203.3 | F26: =SUM(F21:F25) -> 5368441.1 | G26: =SUM(G21:G25) -> 6607761.7 | H26: =SUM(H21:H25) -> 7297531.4 | I26: =SUM(I21:I25) -> 5586859.9 | J26: =SUM(J21:J25) -> 6964775.1 | ... R26: =SUM(R21:R25) -> 11998788 | S26: =AVERAGE(C26:R26) -> 7420396.9
B28: Resposta 2: O faturamento médio mensal da empresa é USD 7,4 MM
B29: Resposta 3: O Mês de maior faturamento foi Out/2019 com um valor total de USD 12,3 MM
A32: 4 - Qual valor total de descontos concedidos sobre as vendas no período? / 5 - Qual país gera maior margem de lucro para a empresa em todo o período de Análise / 6 - Qual país representa o maior faturamento da empresa em todo período?
B34: Tabela 3 - Análise econômica por Região
B35: Países | C35: Faturamento Bruto | D35: Descontos | E35: Faturamento Líquido | F35: Custos | G35: Lucro | H35: Margem de Lucro
B36: Canadá | C36: =SUMIFS(BD!D:D,BD!$B:$B,Solucao!$B36) -> 26932164 | D36: =SUMIFS(BD!E:E,BD!$B:$B,Solucao!$B36) -> 2044508.6 | E36: =SUMIFS(BD!F:F,BD!$B:$B,Solucao!$B36) -> 24887655 | F36: =SUMIFS(BD!G:G,BD!$B:$B,Solucao!$B36) -> 21575836 | G36: =SUMIFS(BD!H:H,BD!$B:$B,Solucao!$B36) -> 3311819 | H36: =G36/E36 -> 0.13307075
B37: Alemanha | C37: =SUMIFS(BD!D:D,BD!$B:$B,Solucao!$B37) -> 24921468 | D37: =SUMIFS(BD!E:E,BD!$B:$B,Solucao!$B37) -> 1416126.7 | E37: =SUMIFS(BD!F:F,BD!$B:$B,Solucao!$B37) -> 23505341 | F37: =SUMIFS(BD!G:G,BD!$B:$B,Solucao!$B37) -> 20094219 | G37: =SUMIFS(BD!H:H,BD!$B:$B,Solucao!$B37) -> 3411122.2 | H37: =G37/E37 -> 0.14512116
B38: França | C38: =SUMIFS(BD!D:D,BD!$B:$B,Solucao!$B38) -> 26081674 | D38: =SUMIFS(BD!E:E,BD!$B:$B,Solucao!$B38) -> 1727502.2 | E38: =SUMIFS(BD!F:F,BD!$B:$B,Solucao!$B38) -> 24354172 | F38: =SUMIFS(BD!G:G,BD!$B:$B,Solucao!$B38) -> 20876597 | G38: =SUMIFS(BD!H:H,BD!$B:$B,Solucao!$B38) -> 3477575.1 | H38: =G38/E38 -> 0.14279176
B39: Chile | C39: =SUMIFS(BD!D:D,BD!$B:$B,Solucao!$B39) -> 22726935 | D39: =SUMIFS(BD!E:E,BD!$B:$B,Solucao!$B39) -> 1777582.9 | E39: =SUMIFS(BD!F:F,BD!$B:$B,Solucao!$B39) -> 20949352 | F39: =SUMIFS(BD!G:G,BD!$B:$B,Solucao!$B39) -> 18290422 | G39: =SUMIFS(BD!H:H,BD!$B:$B,Solucao!$B39) -> 2658929.8 | H39: =G39/E39 -> 0.12692182
B40: EUA | C40: =SUMIFS(BD!D:D,BD!$B:$B,Solucao!$B40) -> 27269358 | D40: =SUMIFS(BD!E:E,BD!$B:$B,Solucao!$B40) -> 2239527.8 | E40: =SUMIFS(BD!F:F,BD!$B:$B,Solucao!$B40) -> 25029830 | F40: =SUMIFS(BD!G:G,BD!$B:$B,Solucao!$B40) -> 22194424 | G40: =SUMIFS(BD!H:H,BD!$B:$B,Solucao!$B40) -> 2835405.9 | H40: =G40/E40 -> 0.11328107
B41: Total | C41: =SUM(C36:C40) -> 1.279316e+08 | D41: =SUM(D36:D40) -> 9205248.2 | E41: =SUM(E36:E40) -> 1.1872635e+08 | F41: =SUM(F36:F40) -> 1.030315e+08 | G41: =SUM(G36:G40) -> 15694852 | H41: =G41/E41 -> 0.1321935
B43: Resposta 4: O valor total de desconto foi de USD 9,2 MM
B44: Resposta 5: O país com maior margem de lucro foi a Alemanha (14,5%)
B45: Resposta 6: O país com maior faturamento líquido foi os EUA (USD 25,0 MM)
A47: 7 - Qual tipo de cliente representa o maior faturamento da empresa em todo período? / 8 - Qual tipo de cliente resulta em uma maior margem de lucro para a empresa?
B49: Clientes | C49: Faturamento Bruto | D49: Descontos | E49: Faturamento Líquido | F49: Custos | G49: Lucro | H49: Margem de Lucro
B50: Governo | C50: =SUMIFS(BD!D:D,BD!$A:$A,Solucao!$B50) -> 56403066 | D50: =SUMIFS(BD!E:E,BD!$A:$A,Solucao!$B50) -> 3898805.8 | E50: =SUMIFS(BD!F:F,BD!$A:$A,Solucao!$B50) -> 52504261 | F50: =SUMIFS(BD!G:G,BD!$A:$A,Solucao!$B50) -> 41584282 | G50: =SUMIFS(BD!H:H,BD!$A:$A,Solucao!$B50) -> 10919978 | H50: =+G50/E50 -> 0.20798271
B51: Médias Empresas | C51: =SUMIFS(BD!D:D,BD!$A:$A,Solucao!$B51) -> 2582670 | D51: =SUMIFS(BD!E:E,BD!$A:$A,Solucao!$B51) -> 200786.92 | E51: =SUMIFS(BD!F:F,BD!$A:$A,Solucao!$B51) -> 2381883.1 | F51: =SUMIFS(BD!G:G,BD!$A:$A,Solucao!$B51) -> 1746100 | G51: =SUMIFS(BD!H:H,BD!$A:$A,Solucao!$B51) -> 635783.07 | H51: =+G51/E51 -> 0.26692455
B52: Vendas Online | C52: =SUMIFS(BD!D:D,BD!$A:$A,Solucao!$B52) -> 1935162 | D52: =SUMIFS(BD!E:E,BD!$A:$A,Solucao!$B52) -> 134568.36 | E52: =SUMIFS(BD!F:F,BD!$A:$A,Solucao!$B52) -> 1800593.6 | F52: =SUMIFS(BD!G:G,BD!$A:$A,Solucao!$B52) -> 491233.8 | G52: =SUMIFS(BD!H:H,BD!$A:$A,Solucao!$B52) -> 1309359.8 | H52: =+G52/E52 -> 0.72718231
B53: Grandes Empresas | C53: =SUMIFS(BD!D:D,BD!$A:$A,Solucao!$B53) -> 21069000 | D53: =SUMIFS(BD!E:E,BD!$A:$A,Solucao!$B53) -> 1457305.6 | E53: =SUMIFS(BD!F:F,BD!$A:$A,Solucao!$B53) -> 19611694 | F53: =SUMIFS(BD!G:G,BD!$A:$A,Solucao!$B53) -> 20568882 | G53: =SUMIFS(BD!H:H,BD!$A:$A,Solucao!$B53) -> -957187.63 | H53: =+G53/E53 -> -0.048806983
B54: Pequenas Empresas | C54: =SUMIFS(BD!D:D,BD!$A:$A,Solucao!$B54) -> 45941700 | D54: =SUMIFS(BD!E:E,BD!$A:$A,Solucao!$B54) -> 3513781.5 | E54: =SUMIFS(BD!F:F,BD!$A:$A,Solucao!$B54) -> 42427918 | F54: =SUMIFS(BD!G:G,BD!$A:$A,Solucao!$B54) -> 38641000 | G54: =SUMIFS(BD!H:H,BD!$A:$A,Solucao!$B54) -> 3786918.5 | H54: =+G54/E54 -> 0.089255345
...

Sheet BD
A1: Tipos de Clientes | B1: País | C1: Produto | D1: Valor Total | E1: Desconto | F1: Valor Total c/ Desconto | G1: Custo Total | H1: Lucro | I1: Data | J1: Mês | K1: Ano
A2: Governo | B2: Canadá | C2: Produto 1 | D2: 32370 | E2: 0 | F2: 32370 | G2: 17803.5 | H2: 14566.5 | I2: 43466 | J2: Janeiro | K2: 2019
A3: Governo | B3: Alemanha | C3: Produto 1 | D3: 26420 | E3: 0 | F3: 26420 | G3: 14531 | H3: 11889 | I3: 43466 | J3: Janeiro | K3: 2019
A4: Médias Empresas | B4: França | C4: Produto 1 | D4: 32670 | E4: 0 | F4: 32670 | G4: 23958 | H4: 8712 | I4: 43617 | J4: Junho | K4: 2019
A5: Médias Empresas | B5: Alemanha | C5: Produto 1 | D5: 13320 | E5: 0 | F5: 13320 | G5: 9768 | H5: 3552 | I5: 43617 | J5: Junho | K5: 2019
A6: Médias Empresas | B6: Chile | C6: Produto 1 | D6: 37050 | E6: 0 | F6: 37050 | G6: 27170 | H6: 9880 | I6: 43617 | J6: Junho | K6: 2019
A7: Governo | B7: Alemanha | C7: Produto 1 | D7: 529550 | E7: 0 | F7: 529550 | G7: 432718 | H7: 96832 | I7: 43800 | J7: Dezembro | K7: 2019
A8: Médias Empresas | B8: Alemanha | C8: Produto 2 | D8: 13815 | E8: 0 | F8: 13815 | G8: 9210 | H8: 4605 | I8: 43525 | J8: Março | K8: 2019
A9: Vendas Online | B9: Canadá | C9: Produto 2 | D9: 30216 | E9: 0 | F9: 30216 | G9: 7554 | H9: 22662 | I9: 43617 | J9: Junho | K9: 2019
A10: Governo | B10: França | C10: Produto 2 | D10: 37980 | E10: 0 | F10: 37980 | G10: 18990 | H10: 18990 | I10: 43617 | J10: Junho | K10: 2019
A11: Vendas Online | B11: Alemanha | C11: Produto 2 | D11: 18540 | E11: 0 | F11: 18540 | G11: 4635 | H11: 13905 | I11: 43617 | J11: Junho | K11: 2019
A12: Médias Empresas | B12: Chile | C12: Produto 2 | D12: 37050 | E12: 0 | F12: 37050 | G12: 24700 | H12: 12350 | I12: 43617 | J12: Junho | K12: 2019
A13: Grandes Empresas | B13: Canadá | C13: Produto 2 | D13: 333187.5 | E13: 0 | F13: 333187.5 | G13: 319860 | H13: 13327.5 | I13: 43647 | J13: Julho | K13: 2019
... A701: Vendas Online | B701: EUA | C701: Produto 5 | D701: 21672 | E701: 3250.8 | F701: 18421.2 | G701: 5418 | H701: 13003.2 | I701: 43586 | J701: Maio | K701: 2019
